Workbook

Sheet Map
A1: Account | B1: Type | C1: PL_Line | D1: Sign
A2: Revenue | B2: Revenue | C2: Net revenue | D2: 1
A3: COGS | B3: Expense | C3: Cost of sales | D3: -1
A4: Salaries | B4: Expense | C4: Operating expense | D4: -1
A5: Marketing | B5: Expense | C5: Operating expense | D5: -1
A6: Rent | B6: Expense | C6: Operating expense | D6: -1
A7: Travel | B7: Expense | C7: Operating expense | D7: -1

Sheet GL
A1: Period | B1: Dept | C1: Account | D1: Version | E1: Amount
A2: 2026-08 | B2: Sales | C2: Revenue | D2: BUD | E2: 300000
A3: 2026-08 | B3: Ops | C3: Revenue | D3: BUD | E3: 200000
A4: 2026-08 | B4: Ops | C4: COGS | D4: BUD | E4: 200000
A5: 2026-08 | B5: Sales | C5: Salaries | D5: BUD | E5: 70000
A6: 2026-08 | B6: Ops | C6: Salaries | D6: BUD | E6: 50000
A7: 2026-08 | B7: Sales | C7: Marketing | D7: BUD | E7: 40000
A8: 2026-08 | B8: Ops | C8: Rent | D8: BUD | E8: 25000
A9: 2026-08 | B9: Sales | C9: Travel | D9: BUD | E9: 5000
A10: 2026-08 | B10: Ops | C10: Travel | D10: BUD | E10: 3000
A11: 2026-08 | B11: Sales | C11: Revenue | D11: ACT | E11: 270000
A12: 2026-08 | B12: Ops | C12: Revenue | D12: ACT | E12: 198000
A13: 2026-08 | B13: Ops | C13: COGS | D13: ACT | E13: 191000
... A37: 2025-08 | B37: Ops | C37: Travel | D37: ACT | E37: 3000

Sheet BvA
A1: Report period | B1: 2026-08
A2: Pct threshold | B2: 0.05
A3: Abs threshold | B3: 5000
A5: Account | B5: Type | C5: Budget | D5: Actual | E5: Variance | F5: Var % | G5: Fav/Unfav | H5: Needs comment
A6: Revenue | B6: =INDEX(Map!$B$2:$B$7,MATCH($A6,Map!$A$2:$A$7,0)) -> Revenue | C6: =SUMIFS(GL!$E$2:$E$37,GL!$C$2:$C$37,$A6,GL!$D$2:$D$37,"BUD",GL!$A$2:$A$37,$B$1) -> 500000 | D6: =SUMIFS(GL!$E$2:$E$37,GL!$C$2:$C$37,$A6,GL!$D$2:$D$37,"ACT",GL!$A$2:$A$37,$B$1) -> 468000 | E6: =D6-C6 -> -32000 | F6: =IF(C6=0,"n/a",E6/ABS(C6)) -> -0.064 | G6: =IF(D6=C6,"On budget",IF((B6="Revenue")=(D6>C6),"Favorable","Unfavorable")) -> Unfavorable | H6: =IF(ISNUMBER(F6),AND(ABS(E6)>=$B$3,ABS(F6)>=$B$2),FALSE()) -> TRUE
A7: COGS | B7: =INDEX(Map!$B$2:$B$7,MATCH($A7,Map!$A$2:$A$7,0)) -> Expense | C7: =SUMIFS(GL!$E$2:$E$37,GL!$C$2:$C$37,$A7,GL!$D$2:$D$37,"BUD",GL!$A$2:$A$37,$B$1) -> 200000 | D7: =SUMIFS(GL!$E$2:$E$37,GL!$C$2:$C$37,$A7,GL!$D$2:$D$37,"ACT",GL!$A$2:$A$37,$B$1) -> 191000 | E7: =D7-C7 -> -9000 | F7: =IF(C7=0,"n/a",E7/ABS(C7)) -> -0.045 | G7: =IF(D7=C7,"On budget",IF((B7="Revenue")=(D7>C7),"Favorable","Unfavorable")) -> Favorable | H7: =IF(ISNUMBER(F7),AND(ABS(E7)>=$B$3,ABS(F7)>=$B$2),FALSE()) -> FALSE
A8: Salaries | B8: =INDEX(Map!$B$2:$B$7,MATCH($A8,Map!$A$2:$A$7,0)) -> Expense | C8: =SUMIFS(GL!$E$2:$E$37,GL!$C$2:$C$37,$A8,GL!$D$2:$D$37,"BUD",GL!$A$2:$A$37,$B$1) -> 120000 | D8: =SUMIFS(GL!$E$2:$E$37,GL!$C$2:$C$37,$A8,GL!$D$2:$D$37,"ACT",GL!$A$2:$A$37,$B$1) -> 124500 | E8: =D8-C8 -> 4500 | F8: =IF(C8=0,"n/a",E8/ABS(C8)) -> 0.0375 | G8: =IF(D8=C8,"On budget",IF((B8="Revenue")=(D8>C8),"Favorable","Unfavorable")) -> Unfavorable | H8: =IF(ISNUMBER(F8),AND(ABS(E8)>=$B$3,ABS(F8)>=$B$2),FALSE()) -> FALSE
A9: Marketing | B9: =INDEX(Map!$B$2:$B$7,MATCH($A9,Map!$A$2:$A$7,0)) -> Expense | C9: =SUMIFS(GL!$E$2:$E$37,GL!$C$2:$C$37,$A9,GL!$D$2:$D$37,"BUD",GL!$A$2:$A$37,$B$1) -> 40000 | D9: =SUMIFS(GL!$E$2:$E$37,GL!$C$2:$C$37,$A9,GL!$D$2:$D$37,"ACT",GL!$A$2:$A$37,$B$1) -> 52000 | E9: =D9-C9 -> 12000 | F9: =IF(C9=0,"n/a",E9/ABS(C9)) -> 0.3 | G9: =IF(D9=C9,"On budget",IF((B9="Revenue")=(D9>C9),"Favorable","Unfavorable")) -> Unfavorable | H9: =IF(ISNUMBER(F9),AND(ABS(E9)>=$B$3,ABS(F9)>=$B$2),FALSE()) -> TRUE
A10: Rent | B10: =INDEX(Map!$B$2:$B$7,MATCH($A10,Map!$A$2:$A$7,0)) -> Expense | C10: =SUMIFS(GL!$E$2:$E$37,GL!$C$2:$C$37,$A10,GL!$D$2:$D$37,"BUD",GL!$A$2:$A$37,$B$1) -> 25000 | D10: =SUMIFS(GL!$E$2:$E$37,GL!$C$2:$C$37,$A10,GL!$D$2:$D$37,"ACT",GL!$A$2:$A$37,$B$1) -> 25000 | E10: =D10-C10 -> 0 | F10: =IF(C10=0,"n/a",E10/ABS(C10)) -> 0 | G10: =IF(D10=C10,"On budget",IF((B10="Revenue")=(D10>C10),"Favorable","Unfavorable")) -> On budget | H10: =IF(ISNUMBER(F10),AND(ABS(E10)>=$B$3,ABS(F10)>=$B$2),FALSE()) -> FALSE
A11: Travel | B11: =INDEX(Map!$B$2:$B$7,MATCH($A11,Map!$A$2:$A$7,0)) -> Expense | C11: =SUMIFS(GL!$E$2:$E$37,GL!$C$2:$C$37,$A11,GL!$D$2:$D$37,"BUD",GL!$A$2:$A$37,$B$1) -> 8000 | D11: =SUMIFS(GL!$E$2:$E$37,GL!$C$2:$C$37,$A11,GL!$D$2:$D$37,"ACT",GL!$A$2:$A$37,$B$1) -> 5100 | E11: =D11-C11 -> -2900 | F11: =IF(C11=0,"n/a",E11/ABS(C11)) -> -0.3625 | G11: =IF(D11=C11,"On budget",IF((B11="Revenue")=(D11>C11),"Favorable","Unfavorable")) -> Favorable | H11: =IF(ISNUMBER(F11),AND(ABS(E11)>=$B$3,ABS(F11)>=$B$2),FALSE()) -> FALSE
A12: Operating income | B12: Revenue | C12: =C6-SUM(C7:C11) -> 107000 | D12: =D6-SUM(D7:D11) -> 70400 | E12: =D12-C12 -> -36600 | F12: =IF(C12=0,"n/a",E12/ABS(C12)) -> -0.34205607 | G12: =IF(D12=C12,"On budget",IF((B12="Revenue")=(D12>C12),"Favorable","Unfavorable")) -> Unfavorable | H12: =IF(ISNUMBER(F12),AND(ABS(E12)>=$B$3,ABS(F12)>=$B$2),FALSE()) -> TRUE
A14: Check: mapped actuals minus all GL actuals (should be 0) | D14: =SUM(D6:D11)-SUMIFS(GL!$E$2:$E$37,GL!$D$2:$D$37,"ACT",GL!$A$2:$A$37,$B$1) -> 0

Sheet Flux
A1: Current period | B1: 2026-08
A2: Prior month | B2: 2026-07
A3: Prior year | B3: 2025-08
A4: Pct threshold | B4: 0.1
A5: Abs threshold | B5: 5000
A7: Account | B7: Current | C7: Prior month | D7: MoM $ | E7: MoM % | F7: Prior year | G7: YoY $ | H7: YoY % | I7: Flag
A8: Revenue | B8: =SUMIFS(GL!$E$2:$E$37,GL!$C$2:$C$37,$A8,GL!$D$2:$D$37,"ACT",GL!$A$2:$A$37,$B$1) -> 468000 | C8: =SUMIFS(GL!$E$2:$E$37,GL!$C$2:$C$37,$A8,GL!$D$2:$D$37,"ACT",GL!$A$2:$A$37,$B$2) -> 455000 | D8: =B8-C8 -> 13000 | E8: =IF(C8=0,"n/a",D8/ABS(C8)) -> 0.028571429 | F8: =SUMIFS(GL!$E$2:$E$37,GL!$C$2:$C$37,$A8,GL!$D$2:$D$37,"ACT",GL!$A$2:$A$37,$B$3) -> 430000 | G8: =B8-F8 -> 38000 | H8: =IF(F8=0,"n/a",G8/ABS(F8)) -> 0.088372093 | I8: =IF(OR(AND(ABS(D8)>=$B$5,ABS(N(E8))>=$B$4),AND(ABS(G8)>=$B$5,ABS(N(H8))>=$B$4)),"Explain","")
A9: COGS | B9: =SUMIFS(GL!$E$2:$E$37,GL!$C$2:$C$37,$A9,GL!$D$2:$D$37,"ACT",GL!$A$2:$A$37,$B$1) -> 191000 | C9: =SUMIFS(GL!$E$2:$E$37,GL!$C$2:$C$37,$A9,GL!$D$2:$D$37,"ACT",GL!$A$2:$A$37,$B$2) -> 186000 | D9: =B9-C9 -> 5000 | E9: =IF(C9=0,"n/a",D9/ABS(C9)) -> 0.02688172 | F9: =SUMIFS(GL!$E$2:$E$37,GL!$C$2:$C$37,$A9,GL!$D$2:$D$37,"ACT",GL!$A$2:$A$37,$B$3) -> 176000 | G9: =B9-F9 -> 15000 | H9: =IF(F9=0,"n/a",G9/ABS(F9)) -> 0.085227273 | I9: =IF(OR(AND(ABS(D9)>=$B$5,ABS(N(E9))>=$B$4),AND(ABS(G9)>=$B$5,ABS(N(H9))>=$B$4)),"Explain","")
A10: Salaries | B10: =SUMIFS(GL!$E$2:$E$37,GL!$C$2:$C$37,$A10,GL!$D$2:$D$37,"ACT",GL!$A$2:$A$37,$B$1) -> 124500 | C10: =SUMIFS(GL!$E$2:$E$37,GL!$C$2:$C$37,$A10,GL!$D$2:$D$37,"ACT",GL!$A$2:$A$37,$B$2) -> 121000 | D10: =B10-C10 -> 3500 | E10: =IF(C10=0,"n/a",D10/ABS(C10)) -> 0.02892562 | F10: =SUMIFS(GL!$E$2:$E$37,GL!$C$2:$C$37,$A10,GL!$D$2:$D$37,"ACT",GL!$A$2:$A$37,$B$3) -> 110000 | G10: =B10-F10 -> 14500 | H10: =IF(F10=0,"n/a",G10/ABS(F10)) -> 0.13181818 | I10: =IF(OR(AND(ABS(D10)>=$B$5,ABS(N(E10))>=$B$4),AND(ABS(G10)>=$B$5,ABS(N(H10))>=$B$4)),"Explain","") -> Explain
A11: Marketing | B11: =SUMIFS(GL!$E$2:$E$37,GL!$C$2:$C$37,$A11,GL!$D$2:$D$37,"ACT",GL!$A$2:$A$37,$B$1) -> 52000 | C11: =SUMIFS(GL!$E$2:$E$37,GL!$C$2:$C$37,$A11,GL!$D$2:$D$37,"ACT",GL!$A$2:$A$37,$B$2) -> 39000 | D11: =B11-C11 -> 13000 | E11: =IF(C11=0,"n/a",D11/ABS(C11)) -> 0.33333333 | F11: =SUMIFS(GL!$E$2:$E$37,GL!$C$2:$C$37,$A11,GL!$D$2:$D$37,"ACT",GL!$A$2:$A$37,$B$3) -> 35000 | G11: =B11-F11 -> 17000 | H11: =IF(F11=0,"n/a",G11/ABS(F11)) -> 0.48571429 | I11: =IF(OR(AND(ABS(D11)>=$B$5,ABS(N(E11))>=$B$4),AND(ABS(G11)>=$B$5,ABS(N(H11))>=$B$4)),"Explain","") -> Explain
A12: Rent | B12: =SUMIFS(GL!$E$2:$E$37,GL!$C$2:$C$37,$A12,GL!$D$2:$D$37,"ACT",GL!$A$2:$A$37,$B$1) -> 25000 | C12: =SUMIFS(GL!$E$2:$E$37,GL!$C$2:$C$37,$A12,GL!$D$2:$D$37,"ACT",GL!$A$2:$A$37,$B$2) -> 25000 | D12: =B12-C12 -> 0 | E12: =IF(C12=0,"n/a",D12/ABS(C12)) -> 0 | F12: =SUMIFS(GL!$E$2:$E$37,GL!$C$2:$C$37,$A12,GL!$D$2:$D$37,"ACT",GL!$A$2:$A$37,$B$3) -> 23000 | G12: =B12-F12 -> 2000 | H12: =IF(F12=0,"n/a",G12/ABS(F12)) -> 0.086956522 | I12: =IF(OR(AND(ABS(D12)>=$B$5,ABS(N(E12))>=$B$4),AND(ABS(G12)>=$B$5,ABS(N(H12))>=$B$4)),"Explain","")
A13: Travel | B13: =SUMIFS(GL!$E$2:$E$37,GL!$C$2:$C$37,$A13,GL!$D$2:$D$37,"ACT",GL!$A$2:$A$37,$B$1) -> 5100 | C13: =SUMIFS(GL!$E$2:$E$37,GL!$C$2:$C$37,$A13,GL!$D$2:$D$37,"ACT",GL!$A$2:$A$37,$B$2) -> 6800 | D13: =B13-C13 -> -1700 | E13: =IF(C13=0,"n/a",D13/ABS(C13)) -> -0.25 | F13: =SUMIFS(GL!$E$2:$E$37,GL!$C$2:$C$37,$A13,GL!$D$2:$D$37,"ACT",GL!$A$2:$A$37,$B$3) -> 7000 | G13: =B13-F13 -> -1900 | H13: =IF(F13=0,"n/a",G13/ABS(F13)) -> -0.27142857 | I13: =IF(OR(AND(ABS(D13)>=$B$5,ABS(N(E13))>=$B$4),AND(ABS(G13)>=$B$5,ABS(N(H13))>=$B$4)),"Explain","")

Sheet PVM
A4: Product | B4: Bud units | C4: Bud price | D4: Act units | E4: Act price | F4: Bud rev | G4: Act rev | H4: Bud mix % | I4: Act units @ bud mix | J4: Price var | K4: Volume var | L4: Mix var | M4: Total var | N4: Check
A5: Basic | B5: 1000 | C5: 50 | D5: 900 | E5: 52 | F5: =B5*C5 -> 50000 | G5: =D5*E5 -> 46800 | H5: =B5/$B$8 -> 0.625 | I5: =$D$8*H5 -> 993.75 | J5: =(E5-C5)*D5 -> 1800 | K5: =(I5-B5)*C5 -> -312.5 | L5: =(D5-I5)*C5 -> -4687.5 | M5: =G5-F5 -> -3200 | N5: =ROUND(J5+K5+L5-M5,6) -> 0
A6: Pro | B6: 500 | C6: 120 | D6: 600 | E6: 115 | F6: =B6*C6 -> 60000 | G6: =D6*E6 -> 69000 | H6: =B6/$B$8 -> 0.3125 | I6: =$D$8*H6 -> 496.875 | J6: =(E6-C6)*D6 -> -3000 | K6: =(I6-B6)*C6 -> -375 | L6: =(D6-I6)*C6 -> 12375 | M6: =G6-F6 -> 9000 | N6: =ROUND(J6+K6+L6-M6,6) -> 0
A7: Enterprise | B7: 100 | C7: 400 | D7: 90 | E7: 420 | F7: =B7*C7 -> 40000 | G7: =D7*E7 -> 37800 | H7: =B7/$B$8 -> 0.0625 | I7: =$D$8*H7 -> 99.375 | J7: =(E7-C7)*D7 -> 1800 | K7: =(I7-B7)*C7 -> -250 | L7: =(D7-I7)*C7 -> -3750 | M7: =G7-F7 -> -2200 | N7: =ROUND(J7+K7+L7-M7,6) -> 0
A8: Total | B8: =SUM(B5:B7) -> 1600 | C8: =F8/B8 -> 93.75 | D8: =SUM(D5:D7) -> 1590 | E8: =G8/D8 -> 96.603774 | F8: =SUM(F5:F7) -> 150000 | G8: =SUM(G5:G7) -> 153600 | H8: =SUM(H5:H7) -> 1 | I8: =SUM(I5:I7) -> 1590 | J8: =SUM(J5:J7) -> 600 | K8: =SUM(K5:K7) -> -937.5 | L8: =SUM(L5:L7) -> 3937.5 | M8: =SUM(M5:M7) -> 3600 | N8: =SUM(N5:N7) -> 0
A10: Waterfall step | B10: Amount
A11: Budget revenue | B11: =F8 -> 150000
A12: Price | B12: =J8 -> 600
A13: Volume | B13: =K8 -> -937.5
A14: Mix | B14: =L8 -> 3937.5
A15: Actual revenue | B15: =G8 -> 153600

Sheet CostVar
A1: Part A - Rate / volume (freight)
A3: Budget shipments | B3: 2000
A4: Budget rate / shipment | B4: 12
A5: Actual shipments | B5: 2300
A6: Actual rate / shipment | B6: 12.5
A8: Budget cost | B8: =B3*B4 -> 24000
A9: Actual cost | B9: =B5*B6 -> 28750
A10: Rate variance | B10: =(B6-B4)*B5 -> 1150 | C10: =IF(B10>0,"Unfavorable",IF(B10<0,"Favorable","None")) -> Unfavorable
A11: Volume variance | B11: =(B5-B3)*B4 -> 3600 | C11: =IF(B11>0,"Unfavorable",IF(B11<0,"Favorable","None")) -> Unfavorable
A12: Total variance | B12: =B9-B8 -> 4750 | C12: =IF(B12>0,"Unfavorable",IF(B12<0,"Favorable","None")) -> Unfavorable
A13: Check (should be 0) | B13: =B10+B11-B12 -> 0
A15: Part B - Flexible budget
A17: Budget units | B17: 10000
A18: Budget price | B18: 20
A19: Budget variable cost / unit | B19: 12
A20: Budget fixed costs | B20: 50000
A21: Actual units | B21: 11000
A22: Actual revenue | B22: 214500
A23: Actual variable costs | B23: 137500
A24: Actual fixed costs | B24: 52000
A26: Line | B26: Static budget | C26: Flexible budget | D26: Actual | E26: Flex-budget variance (Actual - Flex) | F26: Sales-volume variance (Flex - Static)
A27: Units | B27: =$B$17 -> 10000 | C27: =$B$21 -> 11000 | D27: =$B$21 -> 11000 | E27: =D27-C27 -> 0 | F27: =C27-B27 -> 1000
A28: Revenue | B28: =B27*$B$18 -> 200000 | C28: =C27*$B$18 -> 220000 | D28: =$B$22 -> 214500 | E28: =D28-C28 -> -5500 | F28: =C28-B28 -> 20000
A29: Variable costs | B29: =B27*$B$19 -> 120000 | C29: =C27*$B$19 -> 132000 | D29: =$B$23 -> 137500 | E29: =D29-C29 -> 5500 | F29: =C29-B29 -> 12000
A30: Contribution margin | B30: =B28-B29 -> 80000 | C30: =C28-C29 -> 88000 | D30: =D28-D29 -> 77000 | E30: =D30-C30 -> -11000 | F30: =C30-B30 -> 8000
A31: Fixed costs | B31: =$B$20 -> 50000 | C31: =$B$20 -> 50000 | D31: =$B$24 -> 52000 | E31: =D31-C31 -> 2000 | F31: =C31-B31 -> 0
A32: Operating income | B32: =B30-B31 -> 30000 | C32: =C30-C31 -> 38000 | D32: =D30-D31 -> 25000 | E32: =D32-C32 -> -13000 | F32: =C32-B32 -> 8000

Sheet PivotLab
A2: Period | B2: 2026-08
A3: Version | B3: ACT
A5: Dept \ Account | B5: Revenue | C5: COGS | D5: Salaries | E5: Marketing | F5: Rent | G5: Travel
A6: Sales | B6: =SUMIFS(GL!$E$2:$E$37,GL!$B$2:$B$37,$A6,GL!$C$2:$C$37,B$5,GL!$A$2:$A$37,$B$2,GL!$D$2:$D$37,$B$3) -> 270000 | C6: =SUMIFS(GL!$E$2:$E$37,GL!$B$2:$B$37,$A6,GL!$C$2:$C$37,C$5,GL!$A$2:$A$37,$B$2,GL!$D$2:$D$37,$B$3) -> 0 | D6: =SUMIFS(GL!$E$2:$E$37,GL!$B$2:$B$37,$A6,GL!$C$2:$C$37,D$5,GL!$A$2:$A$37,$B$2,GL!$D$2:$D$37,$B$3) -> 72000 | E6: =SUMIFS(GL!$E$2:$E$37,GL!$B$2:$B$37,$A6,GL!$C$2:$C$37,E$5,GL!$A$2:$A$37,$B$2,GL!$D$2:$D$37,$B$3) -> 52000 | F6: =SUMIFS(GL!$E$2:$E$37,GL!$B$2:$B$37,$A6,GL!$C$2:$C$37,F$5,GL!$A$2:$A$37,$B$2,GL!$D$2:$D$37,$B$3) -> 0 | G6: =SUMIFS(GL!$E$2:$E$37,GL!$B$2:$B$37,$A6,GL!$C$2:$C$37,G$5,GL!$A$2:$A$37,$B$2,GL!$D$2:$D$37,$B$3) -> 3600
A7: Ops | B7: =SUMIFS(GL!$E$2:$E$37,GL!$B$2:$B$37,$A7,GL!$C$2:$C$37,B$5,GL!$A$2:$A$37,$B$2,GL!$D$2:$D$37,$B$3) -> 198000 | C7: =SUMIFS(GL!$E$2:$E$37,GL!$B$2:$B$37,$A7,GL!$C$2:$C$37,C$5,GL!$A$2:$A$37,$B$2,GL!$D$2:$D$37,$B$3) -> 191000 | D7: =SUMIFS(GL!$E$2:$E$37,GL!$B$2:$B$37,$A7,GL!$C$2:$C$37,D$5,GL!$A$2:$A$37,$B$2,GL!$D$2:$D$37,$B$3) -> 52500 | E7: =SUMIFS(GL!$E$2:$E$37,GL!$B$2:$B$37,$A7,GL!$C$2:$C$37,E$5,GL!$A$2:$A$37,$B$2,GL!$D$2:$D$37,$B$3) -> 0 | F7: =SUMIFS(GL!$E$2:$E$37,GL!$B$2:$B$37,$A7,GL!$C$2:$C$37,F$5,GL!$A$2:$A$37,$B$2,GL!$D$2:$D$37,$B$3) -> 25000 | G7: =SUMIFS(GL!$E$2:$E$37,GL!$B$2:$B$37,$A7,GL!$C$2:$C$37,G$5,GL!$A$2:$A$37,$B$2,GL!$D$2:$D$37,$B$3) -> 1500
A8: Total | B8: =SUM(B6:B7) -> 468000 | C8: =SUM(C6:C7) -> 191000 | D8: =SUM(D6:D7) -> 124500 | E8: =SUM(E6:E7) -> 52000 | F8: =SUM(F6:F7) -> 25000 | G8: =SUM(G6:G7) -> 5100
A10: Check: cross-tab total vs BvA actuals (should be 0) | B10: =SUM(B8:G8)-SUM(BvA!D6:D11) -> 0

Sheet Book
A1: ID | B1: Date | C1: Amount | D1: Ref | E1: Status | F1: Matched bank ID | G1: Duplicate?
A2: B1 | B2: 46236 | C2: 1200 | D2: INV1001 | E2: =IF(COUNTIFS(Bank!$D$2:$D$5,$D2,Bank!$C$2:$C$5,$C2)>0,"Exact",IF(F2<>"","Tolerance","Unmatched")) -> Exact | F2: =IFERROR(LOOKUP(2,1/((Bank!$D$2:$D$5=$D2)*(ABS(Bank!$C$2:$C$5-$C2)<=BankRec!$B$2)*(ABS(Bank!$B$2:$B$5-$B2)<=BankRec!$B$3)),Bank!$A$2:$A$5),"") -> K1 | G2: =IF(COUNTIFS($D$2:$D$6,$D2,$C$2:$C$6,$C2)>1,"DUPLICATE","")
A3: B2 | B3: 46239 | C3: -350 | D3: CHK2201 | E3: =IF(COUNTIFS(Bank!$D$2:$D$5,$D3,Bank!$C$2:$C$5,$C3)>0,"Exact",IF(F3<>"","Tolerance","Unmatched")) -> Exact | F3: =IFERROR(LOOKUP(2,1/((Bank!$D$2:$D$5=$D3)*(ABS(Bank!$C$2:$C$5-$C3)<=BankRec!$B$2)*(ABS(Bank!$B$2:$B$5-$B3)<=BankRec!$B$3)),Bank!$A$2:$A$5),"") -> K2 | G3: =IF(COUNTIFS($D$2:$D$6,$D3,$C$2:$C$6,$C3)>1,"DUPLICATE","")
A4: B3 | B4: 46244 | C4: 4999.5 | D4: INV1002 | E4: =IF(COUNTIFS(Bank!$D$2:$D$5,$D4,Bank!$C$2:$C$5,$C4)>0,"Exact",IF(F4<>"","Tolerance","Unmatched")) -> Tolerance | F4: =IFERROR(LOOKUP(2,1/((Bank!$D$2:$D$5=$D4)*(ABS(Bank!$C$2:$C$5-$C4)<=BankRec!$B$2)*(ABS(Bank!$B$2:$B$5-$B4)<=BankRec!$B$3)),Bank!$A$2:$A$5),"") -> K3 | G4: =IF(COUNTIFS($D$2:$D$6,$D4,$C$2:$C$6,$C4)>1,"DUPLICATE","")
A5: B4 | B5: 46262 | C5: -2000 | D5: CHK2202 | E5: =IF(COUNTIFS(Bank!$D$2:$D$5,$D5,Bank!$C$2:$C$5,$C5)>0,"Exact",IF(F5<>"","Tolerance","Unmatched")) -> Unmatched | F5: =IFERROR(LOOKUP(2,1/((Bank!$D$2:$D$5=$D5)*(ABS(Bank!$C$2:$C$5-$C5)<=BankRec!$B$2)*(ABS(Bank!$B$2:$B$5-$B5)<=BankRec!$B$3)),Bank!$A$2:$A$5),"") | G5: =IF(COUNTIFS($D$2:$D$6,$D5,$C$2:$C$6,$C5)>1,"DUPLICATE","")
A6: B5 | B6: 46265 | C6: 780 | D6: DEP0831 | E6: =IF(COUNTIFS(Bank!$D$2:$D$5,$D6,Bank!$C$2:$C$5,$C6)>0,"Exact",IF(F6<>"","Tolerance","Unmatched")) -> Unmatched | F6: =IFERROR(LOOKUP(2,1/((Bank!$D$2:$D$5=$D6)*(ABS(Bank!$C$2:$C$5-$C6)<=BankRec!$B$2)*(ABS(Bank!$B$2:$B$5-$B6)<=BankRec!$B$3)),Bank!$A$2:$A$5),"") | G6: =IF(COUNTIFS($D$2:$D$6,$D6,$C$2:$C$6,$C6)>1,"DUPLICATE","")

Sheet Bank
A1: ID | B1: Date | C1: Amount | D1: Ref | E1: Status | F1: Matched book ID
A2: K1 | B2: 46237 | C2: 1200 | D2: INV1001 | E2: =IF(COUNTIFS(Book!$D$2:$D$6,$D2,Book!$C$2:$C$6,$C2)>0,"Exact",IF(F2<>"","Tolerance","Unmatched")) -> Exact | F2: =IFERROR(LOOKUP(2,1/((Book!$D$2:$D$6=$D2)*(ABS(Book!$C$2:$C$6-$C2)<=BankRec!$B$2)*(ABS(Book!$B$2:$B$6-$B2)<=BankRec!$B$3)),Book!$A$2:$A$6),"") -> B1
A3: K2 | B3: 46241 | C3: -350 | D3: CHK2201 | E3: =IF(COUNTIFS(Book!$D$2:$D$6,$D3,Book!$C$2:$C$6,$C3)>0,"Exact",IF(F3<>"","Tolerance","Unmatched")) -> Exact | F3: =IFERROR(LOOKUP(2,1/((Book!$D$2:$D$6=$D3)*(ABS(Book!$C$2:$C$6-$C3)<=BankRec!$B$2)*(ABS(Book!$B$2:$B$6-$B3)<=BankRec!$B$3)),Book!$A$2:$A$6),"") -> B2
A4: K3 | B4: 46245 | C4: 4995 | D4: INV1002 | E4: =IF(COUNTIFS(Book!$D$2:$D$6,$D4,Book!$C$2:$C$6,$C4)>0,"Exact",IF(F4<>"","Tolerance","Unmatched")) -> Tolerance | F4: =IFERROR(LOOKUP(2,1/((Book!$D$2:$D$6=$D4)*(ABS(Book!$C$2:$C$6-$C4)<=BankRec!$B$2)*(ABS(Book!$B$2:$B$6-$B4)<=BankRec!$B$3)),Book!$A$2:$A$6),"") -> B3
A5: K4 | B5: 46249 | C5: -25 | D5: FEE | E5: =IF(COUNTIFS(Book!$D$2:$D$6,$D5,Book!$C$2:$C$6,$C5)>0,"Exact",IF(F5<>"","Tolerance","Unmatched")) -> Unmatched | F5: =IFERROR(LOOKUP(2,1/((Book!$D$2:$D$6=$D5)*(ABS(Book!$C$2:$C$6-$C5)<=BankRec!$B$2)*(ABS(Book!$B$2:$B$6-$B5)<=BankRec!$B$3)),Book!$A$2:$A$6),"")

Sheet BankRec
A1: Bank reconciliation - August 2026
A2: Amount tolerance | B2: 5
A3: Day tolerance | B3: 3
A5: Balance per bank statement | B5: 10000
A6: Balance per GL | B6: 8809.5
A8: BANK SIDE
A9: Balance per bank | B9: =B5 -> 10000
A10: + Deposits in transit | B10: =SUMIFS(Book!$C$2:$C$6,Book!$E$2:$E$6,"Unmatched",Book!$C$2:$C$6,">0") -> 780
A11: - Outstanding checks | B11: =-SUMIFS(Book!$C$2:$C$6,Book!$E$2:$E$6,"Unmatched",Book!$C$2:$C$6,"<0") -> 2000
A12: Adjusted bank balance | B12: =B9+B10-B11 -> 8780
A13: BOOK SIDE
A14: Balance per GL | B14: =B6 -> 8809.5
A15: +/- Bank-only items (fees, interest) | B15: =SUMIFS(Bank!$C$2:$C$5,Bank!$E$2:$E$5,"Unmatched") -> -25
A16: - Book errors (book minus bank on tolerance matches) | B16: =SUMIFS(Book!$C$2:$C$6,Book!$E$2:$E$6,"Tolerance")-SUMIFS(Bank!$C$2:$C$5,Bank!$E$2:$E$5,"Tolerance") -> 4.5
A17: Adjusted book balance | B17: =B14+B15-B16 -> 8780
A19: Difference | B19: =ROUND(B12-B17,2) -> 0
A20: Status | B20: =IF(B19=0,"Reconciled","Difference: "&TEXT(B19,"#,##0.00")) -> Reconciled
A22: Journal entry needed (bank fee + short-paid wire) | B22: =-(B15-B16) -> 29.5

Sheet AR
A1: Invoice | B1: Customer | C1: Due date | D1: Open amount | E1: Days past due | F1: Bucket | H1: As of
A2: A1 | B2: Acme | C2: 46157 | D2: 3000 | E2: =$H$2-C2 -> 108 | F2: =IF(E2<=0,"Current",IF(E2<=30,"1-30",IF(E2<=60,"31-60",IF(E2<=90,"61-90","90+")))) -> 90+ | H2: 46265
A3: A2 | B3: Beta | C3: 46223 | D3: 1500 | E3: =$H$2-C3 -> 42 | F3: =IF(E3<=0,"Current",IF(E3<=30,"1-30",IF(E3<=60,"31-60",IF(E3<=90,"61-90","90+")))) -> 31-60
A4: A3 | B4: Acme | C4: 46259 | D4: 2200 | E4: =$H$2-C4 -> 6 | F4: =IF(E4<=0,"Current",IF(E4<=30,"1-30",IF(E4<=60,"31-60",IF(E4<=90,"61-90","90+")))) -> 1-30
A5: A4 | B5: Cyan | C5: 46275 | D5: 900 | E5: =$H$2-C5 -> -10 | F5: =IF(E5<=0,"Current",IF(E5<=30,"1-30",IF(E5<=60,"31-60",IF(E5<=90,"61-90","90+")))) -> Current
A6: A5 | B6: Beta | C6: 46198 | D6: 1200 | E6: =$H$2-C6 -> 67 | F6: =IF(E6<=0,"Current",IF(E6<=30,"1-30",IF(E6<=60,"31-60",IF(E6<=90,"61-90","90+")))) -> 61-90
A7: A6 | B7: Cyan | C7: 46244 | D7: 650 | E7: =$H$2-C7 -> 21 | F7: =IF(E7<=0,"Current",IF(E7<=30,"1-30",IF(E7<=60,"31-60",IF(E7<=90,"61-90","90+")))) -> 1-30

Sheet ARSummary
A3: Bucket | B3: Amount | C3: % of total | D3: Reserve % | E3: Allowance
A4: Current | B4: =SUMIFS(AR!$D$2:$D$7,AR!$F$2:$F$7,$A4) -> 900 | C4: =B4/$B$9 -> 0.095238095 | D4: 0.005 | E4: =B4*D4 -> 4.5
A5: 1-30 | B5: =SUMIFS(AR!$D$2:$D$7,AR!$F$2:$F$7,$A5) -> 2850 | C5: =B5/$B$9 -> 0.3015873 | D5: 0.02 | E5: =B5*D5 -> 57
A6: 31-60 | B6: =SUMIFS(AR!$D$2:$D$7,AR!$F$2:$F$7,$A6) -> 1500 | C6: =B6/$B$9 -> 0.15873016 | D6: 0.05 | E6: =B6*D6 -> 75
A7: 61-90 | B7: =SUMIFS(AR!$D$2:$D$7,AR!$F$2:$F$7,$A7) -> 1200 | C7: =B7/$B$9 -> 0.12698413 | D7: 0.15 | E7: =B7*D7 -> 180
A8: 90+ | B8: =SUMIFS(AR!$D$2:$D$7,AR!$F$2:$F$7,$A8) -> 3000 | C8: =B8/$B$9 -> 0.31746032 | D8: 0.5 | E8: =B8*D8 -> 1500
A9: Total | B9: =SUM(B4:B8) -> 9450 | E9: =SUMPRODUCT(B4:B8,D4:D8) -> 1816.5
A11: Customer \ Bucket | B11: Current | C11: 1-30 | D11: 31-60 | E11: 61-90 | F11: 90+ | G11: Total
A12: Acme | B12: =SUMIFS(AR!$D$2:$D$7,AR!$B$2:$B$7,$A12,AR!$F$2:$F$7,B$11) -> 0 | C12: =SUMIFS(AR!$D$2:$D$7,AR!$B$2:$B$7,$A12,AR!$F$2:$F$7,C$11) -> 2200 | D12: =SUMIFS(AR!$D$2:$D$7,AR!$B$2:$B$7,$A12,AR!$F$2:$F$7,D$11) -> 0 | E12: =SUMIFS(AR!$D$2:$D$7,AR!$B$2:$B$7,$A12,AR!$F$2:$F$7,E$11) -> 0 | F12: =SUMIFS(AR!$D$2:$D$7,AR!$B$2:$B$7,$A12,AR!$F$2:$F$7,F$11) -> 3000 | G12: =SUM(B12:F12) -> 5200
A13: Beta | B13: =SUMIFS(AR!$D$2:$D$7,AR!$B$2:$B$7,$A13,AR!$F$2:$F$7,B$11) -> 0 | C13: =SUMIFS(AR!$D$2:$D$7,AR!$B$2:$B$7,$A13,AR!$F$2:$F$7,C$11) -> 0 | D13: =SUMIFS(AR!$D$2:$D$7,AR!$B$2:$B$7,$A13,AR!$F$2:$F$7,D$11) -> 1500 | E13: =SUMIFS(AR!$D$2:$D$7,AR!$B$2:$B$7,$A13,AR!$F$2:$F$7,E$11) -> 1200 | F13: =SUMIFS(AR!$D$2:$D$7,AR!$B$2:$B$7,$A13,AR!$F$2:$F$7,F$11) -> 0 | G13: =SUM(B13:F13) -> 2700
A14: Cyan | B14: =SUMIFS(AR!$D$2:$D$7,AR!$B$2:$B$7,$A14,AR!$F$2:$F$7,B$11) -> 900 | C14: =SUMIFS(AR!$D$2:$D$7,AR!$B$2:$B$7,$A14,AR!$F$2:$F$7,C$11) -> 650 | D14: =SUMIFS(AR!$D$2:$D$7,AR!$B$2:$B$7,$A14,AR!$F$2:$F$7,D$11) -> 0 | E14: =SUMIFS(AR!$D$2:$D$7,AR!$B$2:$B$7,$A14,AR!$F$2:$F$7,E$11) -> 0 | F14: =SUMIFS(AR!$D$2:$D$7,AR!$B$2:$B$7,$A14,AR!$F$2:$F$7,F$11) -> 0 | G14: =SUM(B14:F14) -> 1550
A17: GL control account (1200-AR) | B17: 9550
A18: Subledger total | B18: =SUM(AR!$D$2:$D$7) -> 9450
A19: Difference (investigate) | B19: =B17-B18 -> 100

Sheet Forecast
A1: Monthly sales history (Jan-2024 to Jun-2026) and forecasts
A2: Train periods (t <=) | B2: 24
A4: Month | B4: t | C4: Sales | D4: MA3 | E4: Month # | F4: Trend (all) | G4: Ratio (all) | H4: Trend (train) | I4: Ratio (train) | K4: Month # | L4: Raw index (all) | M4: Seasonal index (all) | N4: Raw index (train) | O4: Seasonal index (train)
A5: 45292 | B5: 1 | C5: 90609 | E5: =MONTH(A5) -> 1 | F5: =INTERCEPT($C$5:$C$34,$B$5:$B$34)+SLOPE($C$5:$C$34,$B$5:$B$34)*B5 -> 99689.662 | G5: =C5/F5 -> 0.90891069 | H5: =INTERCEPT($C$5:$C$28,$B$5:$B$28)+SLOPE($C$5:$C$28,$B$5:$B$28)*B5 -> 98072.94 | I5: =C5/H5 -> 0.92389399 | K5: 1 | L5: =AVERAGEIFS($G$5:$G$34,$E$5:$E$34,K5) -> 0.88850213 | M5: =L5/AVERAGE($L$5:$L$16) -> 0.88430454 | N5: =AVERAGEIFS($I$5:$I$34,$E$5:$E$34,K5,$B$5:$B$34,"<="&$B$2) -> 0.90165236 | O5: =N5/AVERAGE($N$5:$N$16) -> 0.90169504
A6: 45323 | B6: 2 | C6: 91300 | E6: =MONTH(A6) -> 2 | F6: =INTERCEPT($C$5:$C$34,$B$5:$B$34)+SLOPE($C$5:$C$34,$B$5:$B$34)*B6 -> 101364.28 | G6: =C6/F6 -> 0.90071176 | H6: =INTERCEPT($C$5:$C$28,$B$5:$B$28)+SLOPE($C$5:$C$28,$B$5:$B$28)*B6 -> 99976.26 | I6: =C6/H6 -> 0.91321679 | K6: 2 | L6: =AVERAGEIFS($G$5:$G$34,$E$5:$E$34,K6) -> 0.90436565 | M6: =L6/AVERAGE($L$5:$L$16) -> 0.90009311 | N6: =AVERAGEIFS($I$5:$I$34,$E$5:$E$34,K6,$B$5:$B$34,"<="&$B$2) -> 0.91336445 | O6: =N6/AVERAGE($N$5:$N$16) -> 0.91340769
A7: 45352 | B7: 3 | C7: 104501 | D7: =AVERAGE(C5:C7) -> 95470 | E7: =MONTH(A7) -> 3 | F7: =INTERCEPT($C$5:$C$34,$B$5:$B$34)+SLOPE($C$5:$C$34,$B$5:$B$34)*B7 -> 103038.9 | G7: =C7/F7 -> 1.0141898 | H7: =INTERCEPT($C$5:$C$28,$B$5:$B$28)+SLOPE($C$5:$C$28,$B$5:$B$28)*B7 -> 101879.58 | I7: =C7/H7 -> 1.0257306 | K7: 3 | L7: =AVERAGEIFS($G$5:$G$34,$E$5:$E$34,K7) -> 0.99411807 | M7: =L7/AVERAGE($L$5:$L$16) -> 0.98942152 | N7: =AVERAGEIFS($I$5:$I$34,$E$5:$E$34,K7,$B$5:$B$34,"<="&$B$2) -> 1.0017025 | O7: =N7/AVERAGE($N$5:$N$16) -> 1.0017499
A8: 45383 | B8: 4 | C8: 108471 | D8: =AVERAGE(C6:C8) -> 101424 | E8: =MONTH(A8) -> 4 | F8: =INTERCEPT($C$5:$C$34,$B$5:$B$34)+SLOPE($C$5:$C$34,$B$5:$B$34)*B8 -> 104713.52 | G8: =C8/F8 -> 1.0358834 | H8: =INTERCEPT($C$5:$C$28,$B$5:$B$28)+SLOPE($C$5:$C$28,$B$5:$B$28)*B8 -> 103782.9 | I8: =C8/H8 -> 1.0451722 | K8: 4 | L8: =AVERAGEIFS($G$5:$G$34,$E$5:$E$34,K8) -> 1.0057608 | M8: =L8/AVERAGE($L$5:$L$16) -> 1.0010092 | N8: =AVERAGEIFS($I$5:$I$34,$E$5:$E$34,K8,$B$5:$B$34,"<="&$B$2) -> 1.009193 | O8: =N8/AVERAGE($N$5:$N$16) -> 1.0092407
A9: 45413 | B9: 5 | C9: 107398 | D9: =AVERAGE(C7:C9) -> 106790 | E9: =MONTH(A9) -> 5 | F9: =INTERCEPT($C$5:$C$34,$B$5:$B$34)+SLOPE($C$5:$C$34,$B$5:$B$34)*B9 -> 106388.14 | G9: =C9/F9 -> 1.0094923 | H9: =INTERCEPT($C$5:$C$28,$B$5:$B$28)+SLOPE($C$5:$C$28,$B$5:$B$28)*B9 -> 105686.22 | I9: =C9/H9 -> 1.0161968 | K9: 5 | L9: =AVERAGEIFS($G$5:$G$34,$E$5:$E$34,K9) -> 1.0225124 | M9: =L9/AVERAGE($L$5:$L$16) -> 1.0176817 | N9: =AVERAGEIFS($I$5:$I$34,$E$5:$E$34,K9,$B$5:$B$34,"<="&$B$2) -> 1.0174814 | O9: =N9/AVERAGE($N$5:$N$16) -> 1.0175296
A10: 45444 | B10: 6 | C10: 115646 | D10: =AVERAGE(C8:C10) -> 110505 | E10: =MONTH(A10) -> 6 | F10: =INTERCEPT($C$5:$C$34,$B$5:$B$34)+SLOPE($C$5:$C$34,$B$5:$B$34)*B10 -> 108062.76 | G10: =C10/F10 -> 1.0701744 | H10: =INTERCEPT($C$5:$C$28,$B$5:$B$28)+SLOPE($C$5:$C$28,$B$5:$B$28)*B10 -> 107589.54 | I10: =C10/H10 -> 1.0748814 | K10: 6 | L10: =AVERAGEIFS($G$5:$G$34,$E$5:$E$34,K10) -> 1.0676457 | M10: =L10/AVERAGE($L$5:$L$16) -> 1.0626017 | N10: =AVERAGEIFS($I$5:$I$34,$E$5:$E$34,K10,$B$5:$B$34,"<="&$B$2) -> 1.0593016 | O10: =N10/AVERAGE($N$5:$N$16) -> 1.0593518
A11: 45474 | B11: 7 | C11: 117976 | D11: =AVERAGE(C9:C11) -> 113673.33 | E11: =MONTH(A11) -> 7 | F11: =INTERCEPT($C$5:$C$34,$B$5:$B$34)+SLOPE($C$5:$C$34,$B$5:$B$34)*B11 -> 109737.37 | G11: =C11/F11 -> 1.0750758 | H11: =INTERCEPT($C$5:$C$28,$B$5:$B$28)+SLOPE($C$5:$C$28,$B$5:$B$28)*B11 -> 109492.86 | I11: =C11/H11 -> 1.0774766 | K11: 7 | L11: =AVERAGEIFS($G$5:$G$34,$E$5:$E$34,K11) -> 1.0725222 | M11: =L11/AVERAGE($L$5:$L$16) -> 1.0674552 | N11: =AVERAGEIFS($I$5:$I$34,$E$5:$E$34,K11,$B$5:$B$34,"<="&$B$2) -> 1.0636161 | O11: =N11/AVERAGE($N$5:$N$16) -> 1.0636665
A12: 45505 | B12: 8 | C12: 116498 | D12: =AVERAGE(C10:C12) -> 116706.67 | E12: =MONTH(A12) -> 8 | F12: =INTERCEPT($C$5:$C$34,$B$5:$B$34)+SLOPE($C$5:$C$34,$B$5:$B$34)*B12 -> 111411.99 | G12: =C12/F12 -> 1.0456504 | H12: =INTERCEPT($C$5:$C$28,$B$5:$B$28)+SLOPE($C$5:$C$28,$B$5:$B$28)*B12 -> 111396.18 | I12: =C12/H12 -> 1.0457988 | K12: 8 | L12: =AVERAGEIFS($G$5:$G$34,$E$5:$E$34,K12) -> 1.0403245 | M12: =L12/AVERAGE($L$5:$L$16) -> 1.0354097 | N12: =AVERAGEIFS($I$5:$I$34,$E$5:$E$34,K12,$B$5:$B$34,"<="&$B$2) -> 1.0298796 | O12: =N12/AVERAGE($N$5:$N$16) -> 1.0299283
A13: 45536 | B13: 9 | C13: 111966 | D13: =AVERAGE(C11:C13) -> 115480 | E13: =MONTH(A13) -> 9 | F13: =INTERCEPT($C$5:$C$34,$B$5:$B$34)+SLOPE($C$5:$C$34,$B$5:$B$34)*B13 -> 113086.61 | G13: =C13/F13 -> 0.99009068 | H13: =INTERCEPT($C$5:$C$28,$B$5:$B$28)+SLOPE($C$5:$C$28,$B$5:$B$28)*B13 -> 113299.5 | I13: =C13/H13 -> 0.98823028 | K13: 9 | L13: =AVERAGEIFS($G$5:$G$34,$E$5:$E$34,K13) -> 0.98171007 | M13: =L13/AVERAGE($L$5:$L$16) -> 0.97707213 | N13: =AVERAGEIFS($I$5:$I$34,$E$5:$E$34,K13,$B$5:$B$34,"<="&$B$2) -> 0.97020821 | O13: =N13/AVERAGE($N$5:$N$16) -> 0.97025414
A14: 45566 | B14: 10 | C14: 109524 | D14: =AVERAGE(C12:C14) -> 112662.67 | E14: =MONTH(A14) -> 10 | F14: =INTERCEPT($C$5:$C$34,$B$5:$B$34)+SLOPE($C$5:$C$34,$B$5:$B$34)*B14 -> 114761.23 | G14: =C14/F14 -> 0.95436411 | H14: =INTERCEPT($C$5:$C$28,$B$5:$B$28)+SLOPE($C$5:$C$28,$B$5:$B$28)*B14 -> 115202.82 | I14: =C14/H14 -> 0.95070586 | K14: 10 | L14: =AVERAGEIFS($G$5:$G$34,$E$5:$E$34,K14) -> 0.94993589 | M14: =L14/AVERAGE($L$5:$L$16) -> 0.94544806 | N14: =AVERAGEIFS($I$5:$I$34,$E$5:$E$34,K14,$B$5:$B$34,"<="&$B$2) -> 0.93719564 | O14: =N14/AVERAGE($N$5:$N$16) -> 0.93724
A15: 45597 | B15: 11 | C15: 111009 | D15: =AVERAGE(C13:C15) -> 110833 | E15: =MONTH(A15) -> 11 | F15: =INTERCEPT($C$5:$C$34,$B$5:$B$34)+SLOPE($C$5:$C$34,$B$5:$B$34)*B15 -> 116435.85 | G15: =C15/F15 -> 0.95339194 | H15: =INTERCEPT($C$5:$C$28,$B$5:$B$28)+SLOPE($C$5:$C$28,$B$5:$B$28)*B15 -> 117106.14 | I15: =C15/H15 -> 0.94793489 | K15: 11 | L15: =AVERAGEIFS($G$5:$G$34,$E$5:$E$34,K15) -> 0.94836446 | M15: =L15/AVERAGE($L$5:$L$16) -> 0.94388406 | N15: =AVERAGEIFS($I$5:$I$34,$E$5:$E$34,K15,$B$5:$B$34,"<="&$B$2) -> 0.93412711 | O15: =N15/AVERAGE($N$5:$N$16) -> 0.93417133
A16: 45627 | B16: 12 | C16: 141356 | D16: =AVERAGE(C14:C16) -> 120629.67 | E16: =MONTH(A16) -> 12 | F16: =INTERCEPT($C$5:$C$34,$B$5:$B$34)+SLOPE($C$5:$C$34,$B$5:$B$34)*B16 -> 118110.47 | G16: =C16/F16 -> 1.1968118 | H16: =INTERCEPT($C$5:$C$28,$B$5:$B$28)+SLOPE($C$5:$C$28,$B$5:$B$28)*B16 -> 119009.46 | I16: =C16/H16 -> 1.1877711 | K16: 12 | L16: =AVERAGEIFS($G$5:$G$34,$E$5:$E$34,K16) -> 1.1811994 | M16: =L16/AVERAGE($L$5:$L$16) -> 1.175619 | N16: =AVERAGEIFS($I$5:$I$34,$E$5:$E$34,K16,$B$5:$B$34,"<="&$B$2) -> 1.1617099 | O16: =N16/AVERAGE($N$5:$N$16) -> 1.1617649
A17: 45658 | B17: 13 | C17: 106332 | D17: =AVERAGE(C15:C17) -> 119565.67 | E17: =MONTH(A17) -> 1 | F17: =INTERCEPT($C$5:$C$34,$B$5:$B$34)+SLOPE($C$5:$C$34,$B$5:$B$34)*B17 -> 119785.09 | G17: =C17/F17 -> 0.8876898 | H17: =INTERCEPT($C$5:$C$28,$B$5:$B$28)+SLOPE($C$5:$C$28,$B$5:$B$28)*B17 -> 120912.79 | I17: =C17/H17 -> 0.87941072 | K17: Average | M17: =AVERAGE(M5:M16) -> 1 | O17: =AVERAGE(O5:O16) -> 1
A18: 45689 | B18: 14 | C18: 112194 | D18: =AVERAGE(C16:C18) -> 119960.67 | E18: =MONTH(A18) -> 2 | F18: =INTERCEPT($C$5:$C$34,$B$5:$B$34)+SLOPE($C$5:$C$34,$B$5:$B$34)*B18 -> 121459.71 | G18: =C18/F18 -> 0.92371375 | H18: =INTERCEPT($C$5:$C$28,$B$5:$B$28)+SLOPE($C$5:$C$28,$B$5:$B$28)*B18 -> 122816.11 | I18: =C18/H18 -> 0.91351211
A19: 45717 | B19: 15 | C19: 121935 | D19: =AVERAGE(C17:C19) -> 113487 | E19: =MONTH(A19) -> 3 | F19: =INTERCEPT($C$5:$C$34,$B$5:$B$34)+SLOPE($C$5:$C$34,$B$5:$B$34)*B19 -> 123134.32 | G19: =C19/F19 -> 0.99026004 | H19: =INTERCEPT($C$5:$C$28,$B$5:$B$28)+SLOPE($C$5:$C$28,$B$5:$B$28)*B19 -> 124719.43 | I19: =C19/H19 -> 0.97767448 | K19: Slope / month | L19: =SLOPE($C$5:$C$34,$B$5:$B$34) -> 1674.6187
A20: 45748 | B20: 16 | C20: 123231 | D20: =AVERAGE(C18:C20) -> 119120 | E20: =MONTH(A20) -> 4 | F20: =INTERCEPT($C$5:$C$34,$B$5:$B$34)+SLOPE($C$5:$C$34,$B$5:$B$34)*B20 -> 124808.94 | G20: =C20/F20 -> 0.98735713 | H20: =INTERCEPT($C$5:$C$28,$B$5:$B$28)+SLOPE($C$5:$C$28,$B$5:$B$28)*B20 -> 126622.75 | I20: =C20/H20 -> 0.97321377 | K20: Intercept | L20: =INTERCEPT($C$5:$C$34,$B$5:$B$34) -> 98015.044
A21: 45778 | B21: 17 | C21: 130938 | D21: =AVERAGE(C19:C21) -> 125368 | E21: =MONTH(A21) -> 5 | F21: =INTERCEPT($C$5:$C$34,$B$5:$B$34)+SLOPE($C$5:$C$34,$B$5:$B$34)*B21 -> 126483.56 | G21: =C21/F21 -> 1.0352175 | H21: =INTERCEPT($C$5:$C$28,$B$5:$B$28)+SLOPE($C$5:$C$28,$B$5:$B$28)*B21 -> 128526.07 | I21: =C21/H21 -> 1.0187661 | K21: R-squared | L21: =RSQ($C$5:$C$34,$B$5:$B$34) -> 0.69432301
A22: 45809 | B22: 18 | C22: 136132 | D22: =AVERAGE(C20:C22) -> 130100.33 | E22: =MONTH(A22) -> 6 | F22: =INTERCEPT($C$5:$C$34,$B$5:$B$34)+SLOPE($C$5:$C$34,$B$5:$B$34)*B22 -> 128158.18 | G22: =C22/F22 -> 1.0622186 | H22: =INTERCEPT($C$5:$C$28,$B$5:$B$28)+SLOPE($C$5:$C$28,$B$5:$B$28)*B22 -> 130429.39 | I22: =C22/H22 -> 1.0437218
A23: 45839 | B23: 19 | C23: 138917 | D23: =AVERAGE(C21:C23) -> 135329 | E23: =MONTH(A23) -> 7 | F23: =INTERCEPT($C$5:$C$34,$B$5:$B$34)+SLOPE($C$5:$C$34,$B$5:$B$34)*B23 -> 129832.8 | G23: =C23/F23 -> 1.0699685 | H23: =INTERCEPT($C$5:$C$28,$B$5:$B$28)+SLOPE($C$5:$C$28,$B$5:$B$28)*B23 -> 132332.71 | I23: =C23/H23 -> 1.0497556
A24: 45870 | B24: 20 | C24: 136110 | D24: =AVERAGE(C22:C24) -> 137053 | E24: =MONTH(A24) -> 8 | F24: =INTERCEPT($C$5:$C$34,$B$5:$B$34)+SLOPE($C$5:$C$34,$B$5:$B$34)*B24 -> 131507.42 | G24: =C24/F24 -> 1.0349987 | H24: =INTERCEPT($C$5:$C$28,$B$5:$B$28)+SLOPE($C$5:$C$28,$B$5:$B$28)*B24 -> 134236.03 | I24: =C24/H24 -> 1.0139603
A25: 45901 | B25: 21 | C25: 129630 | D25: =AVERAGE(C23:C25) -> 134885.67 | E25: =MONTH(A25) -> 9 | F25: =INTERCEPT($C$5:$C$34,$B$5:$B$34)+SLOPE($C$5:$C$34,$B$5:$B$34)*B25 -> 133182.04 | G25: =C25/F25 -> 0.97332947 | H25: =INTERCEPT($C$5:$C$28,$B$5:$B$28)+SLOPE($C$5:$C$28,$B$5:$B$28)*B25 -> 136139.35 | I25: =C25/H25 -> 0.95218613
A26: 45931 | B26: 22 | C26: 127508 | D26: =AVERAGE(C24:C26) -> 131082.67 | E26: =MONTH(A26) -> 10 | F26: =INTERCEPT($C$5:$C$34,$B$5:$B$34)+SLOPE($C$5:$C$34,$B$5:$B$34)*B26 -> 134856.65 | G26: =C26/F26 -> 0.94550766 | H26: =INTERCEPT($C$5:$C$28,$B$5:$B$28)+SLOPE($C$5:$C$28,$B$5:$B$28)*B26 -> 138042.67 | I26: =C26/H26 -> 0.92368541
A27: 45962 | B27: 23 | C27: 128795 | D27: =AVERAGE(C25:C27) -> 128644.33 | E27: =MONTH(A27) -> 11 | F27: =INTERCEPT($C$5:$C$34,$B$5:$B$34)+SLOPE($C$5:$C$34,$B$5:$B$34)*B27 -> 136531.27 | G27: =C27/F27 -> 0.94333699 | H27: =INTERCEPT($C$5:$C$28,$B$5:$B$28)+SLOPE($C$5:$C$28,$B$5:$B$28)*B27 -> 139945.99 | I27: =C27/H27 -> 0.92031933
A28: 45992 | B28: 24 | C28: 161091 | D28: =AVERAGE(C26:C28) -> 139131.33 | E28: =MONTH(A28) -> 12 | F28: =INTERCEPT($C$5:$C$34,$B$5:$B$34)+SLOPE($C$5:$C$34,$B$5:$B$34)*B28 -> 138205.89 | G28: =C28/F28 -> 1.1655871 | H28: =INTERCEPT($C$5:$C$28,$B$5:$B$28)+SLOPE($C$5:$C$28,$B$5:$B$28)*B28 -> 141849.31 | I28: =C28/H28 -> 1.1356488
A29: 46023 | B29: 25 | C29: 121543 | D29: =AVERAGE(C27:C29) -> 137143 | E29: =MONTH(A29) -> 1 | F29: =INTERCEPT($C$5:$C$34,$B$5:$B$34)+SLOPE($C$5:$C$34,$B$5:$B$34)*B29 -> 139880.51 | G29: =C29/F29 -> 0.86890589 | H29: =INTERCEPT($C$5:$C$28,$B$5:$B$28)+SLOPE($C$5:$C$28,$B$5:$B$28)*B29 -> 143752.63 | I29: =C29/H29 -> 0.84550105
A30: 46054 | B30: 26 | C30: 125796 | D30: =AVERAGE(C28:C30) -> 136143.33 | E30: =MONTH(A30) -> 2 | F30: =INTERCEPT($C$5:$C$34,$B$5:$B$34)+SLOPE($C$5:$C$34,$B$5:$B$34)*B30 -> 141555.13 | G30: =C30/F30 -> 0.88867143 | H30: =INTERCEPT($C$5:$C$28,$B$5:$B$28)+SLOPE($C$5:$C$28,$B$5:$B$28)*B30 -> 145655.95 | I30: =C30/H30 -> 0.86365163
A31: 46082 | B31: 27 | C31: 140065 | D31: =AVERAGE(C29:C31) -> 129134.67 | E31: =MONTH(A31) -> 3 | F31: =INTERCEPT($C$5:$C$34,$B$5:$B$34)+SLOPE($C$5:$C$34,$B$5:$B$34)*B31 -> 143229.75 | G31: =C31/F31 -> 0.97790439 | H31: =INTERCEPT($C$5:$C$28,$B$5:$B$28)+SLOPE($C$5:$C$28,$B$5:$B$28)*B31 -> 147559.27 | I31: =C31/H31 -> 0.94921179
A32: 46113 | B32: 28 | C32: 144041 | D32: =AVERAGE(C30:C32) -> 136634 | E32: =MONTH(A32) -> 4 | F32: =INTERCEPT($C$5:$C$34,$B$5:$B$34)+SLOPE($C$5:$C$34,$B$5:$B$34)*B32 -> 144904.37 | G32: =C32/F32 -> 0.99404182 | H32: =INTERCEPT($C$5:$C$28,$B$5:$B$28)+SLOPE($C$5:$C$28,$B$5:$B$28)*B32 -> 149462.59 | I32: =C32/H32 -> 0.9637261
A33: 46143 | B33: 29 | C33: 149925 | D33: =AVERAGE(C31:C33) -> 144677 | E33: =MONTH(A33) -> 5 | F33: =INTERCEPT($C$5:$C$34,$B$5:$B$34)+SLOPE($C$5:$C$34,$B$5:$B$34)*B33 -> 146578.99 | G33: =C33/F33 -> 1.0228274 | H33: =INTERCEPT($C$5:$C$28,$B$5:$B$28)+SLOPE($C$5:$C$28,$B$5:$B$28)*B33 -> 151365.91 | I33: =C33/H33 -> 0.9904806
A34: 46174 | B34: 30 | C34: 158712 | D34: =AVERAGE(C32:C34) -> 150892.67 | E34: =MONTH(A34) -> 6 | F34: =INTERCEPT($C$5:$C$34,$B$5:$B$34)+SLOPE($C$5:$C$34,$B$5:$B$34)*B34 -> 148253.6 | G34: =C34/F34 -> 1.070544 | H34: =INTERCEPT($C$5:$C$28,$B$5:$B$28)+SLOPE($C$5:$C$28,$B$5:$B$28)*B34 -> 153269.23 | I34: =C34/H34 -> 1.0355112
A37: Month | B37: t | C37: Linear (FORECAST.LINEAR) | D37: Linear (TREND) | E37: Trend x season
A38: =EDATE($A$34,1) -> 46204 | B38: =$B$34+1 -> 31 | C38: =_xlfn.FORECAST.LINEAR(B38,$C$5:$C$34,$B$5:$B$34) -> 149928.22 | D38: =TREND($C$5:$C$34,$B$5:$B$34,B38) -> 149928.22 | E38: =C38*INDEX($M$5:$M$16,MONTH(A38)) -> 160041.66
A39: =EDATE(A38,1) -> 46235 | B39: =B38+1 -> 32 | C39: =_xlfn.FORECAST.LINEAR(B39,$C$5:$C$34,$B$5:$B$34) -> 151602.84 | D39: =TREND($C$5:$C$34,$B$5:$B$34,B39) -> 151602.84 | E39: =C39*INDEX($M$5:$M$16,MONTH(A39)) -> 156971.05
A40: =EDATE(A39,1) -> 46266 | B40: =B39+1 -> 33 | C40: =_xlfn.FORECAST.LINEAR(B40,$C$5:$C$34,$B$5:$B$34) -> 153277.46 | D40: =TREND($C$5:$C$34,$B$5:$B$34,B40) -> 153277.46 | E40: =C40*INDEX($M$5:$M$16,MONTH(A40)) -> 149763.14
A41: =EDATE(A40,1) -> 46296 | B41: =B40+1 -> 34 | C41: =_xlfn.FORECAST.LINEAR(B41,$C$5:$C$34,$B$5:$B$34) -> 154952.08 | D41: =TREND($C$5:$C$34,$B$5:$B$34,B41) -> 154952.08 | E41: =C41*INDEX($M$5:$M$16,MONTH(A41)) -> 146499.14
A42: =EDATE(A41,1) -> 46327 | B42: =B41+1 -> 35 | C42: =_xlfn.FORECAST.LINEAR(B42,$C$5:$C$34,$B$5:$B$34) -> 156626.7 | D42: =TREND($C$5:$C$34,$B$5:$B$34,B42) -> 156626.7 | E42: =C42*INDEX($M$5:$M$16,MONTH(A42)) -> 147837.44
A43: =EDATE(A42,1) -> 46357 | B43: =B42+1 -> 36 | C43: =_xlfn.FORECAST.LINEAR(B43,$C$5:$C$34,$B$5:$B$34) -> 158301.32 | D43: =TREND($C$5:$C$34,$B$5:$B$34,B43) -> 158301.32 | E43: =C43*INDEX($M$5:$M$16,MONTH(A43)) -> 186102.04
...

Sheet Drivers
A1: Driver-based subscription revenue forecast
A3: Driver | B3: Downside | C3: Base | D3: Upside | E3: Active
A4: New customers / month | B4: 60 | C4: 80 | D4: 100 | E4: =INDEX(B4:D4,$C$8) -> 80
A5: Monthly churn | B5: 0.03 | C5: 0.02 | D5: 0.015 | E5: =INDEX(B5:D5,$C$8) -> 0.02
A6: ARPU ($ / month) | B6: 90 | C6: 95 | D6: 98 | E6: =INDEX(B6:D6,$C$8) -> 95
A8: Scenario # (1=Down, 2=Base, 3=Up) | C8: 2
A9: Active scenario name | C9: =INDEX($B$3:$D$3,$C$8) -> Base
A10: Starting customers | B10: 1200
A13: Month | B13: 46296 | C13: =EDATE(B13,1) -> 46327 | D13: =EDATE(C13,1) -> 46357 | E13: =EDATE(D13,1) -> 46388 | F13: =EDATE(E13,1) -> 46419 | G13: =EDATE(F13,1) -> 46447 | H13: 6-mo total
A14: Opening customers | B14: =$B$10 -> 1200 | C14: =B17 -> 1256 | D14: =C17 -> 1310.88 | E14: =D17 -> 1364.6624 | F14: =E17 -> 1417.3692 | G14: =F17 -> 1469.0218
A15: Churned | B15: =-B14*$E$5 -> -24 | C15: =-C14*$E$5 -> -25.12 | D15: =-D14*$E$5 -> -26.2176 | E15: =-E14*$E$5 -> -27.293248 | F15: =-F14*$E$5 -> -28.347383 | G15: =-G14*$E$5 -> -29.380435
A16: New | B16: =$E$4 -> 80 | C16: =$E$4 -> 80 | D16: =$E$4 -> 80 | E16: =$E$4 -> 80 | F16: =$E$4 -> 80 | G16: =$E$4 -> 80
A17: Closing customers | B17: =B14+B15+B16 -> 1256 | C17: =C14+C15+C16 -> 1310.88 | D17: =D14+D15+D16 -> 1364.6624 | E17: =E14+E15+E16 -> 1417.3692 | F17: =F14+F15+F16 -> 1469.0218 | G17: =G14+G15+G16 -> 1519.6413
A18: Revenue | B18: =B17*$E$6 -> 119320 | C18: =C17*$E$6 -> 124533.6 | D18: =D17*$E$6 -> 129642.93 | E18: =E17*$E$6 -> 134650.07 | F18: =F17*$E$6 -> 139557.07 | G18: =G17*$E$6 -> 144365.93 | H18: =SUM(B18:G18) -> 792069.59
A21: 6-mo revenue by scenario (closed form) | B21: =B6*SUMPRODUCT($B$10*(1-B5)^$B$25:$G$25+B4*(1-(1-B5)^$B$25:$G$25)/B5) -> 691158.83 | C21: =C6*SUMPRODUCT($B$10*(1-C5)^$B$25:$G$25+C4*(1-(1-C5)^$B$25:$G$25)/C5) -> 792069.59 | D21: =D6*SUMPRODUCT($B$10*(1-D5)^$B$25:$G$25+D4*(1-(1-D5)^$B$25:$G$25)/D5) -> 870199.82
A25: Helper: month index k | B25: 1 | C25: 2 | D25: 3 | E25: 4 | F25: 5 | G25: 6
A28: Churn \ ARPU | B28: 85 | C28: 90 | D28: 95 | E28: 100 | F28: 105
A29: 0.01 | B29: =B$28*SUMPRODUCT($B$10*(1-$A29)^$B$25:$G$25+$E$4*(1-(1-$A29)^$B$25:$G$25)/$A29) -> 731377.11 | C29: =C$28*SUMPRODUCT($B$10*(1-$A29)^$B$25:$G$25+$E$4*(1-(1-$A29)^$B$25:$G$25)/$A29) -> 774399.29 | D29: =D$28*SUMPRODUCT($B$10*(1-$A29)^$B$25:$G$25+$E$4*(1-(1-$A29)^$B$25:$G$25)/$A29) -> 817421.47 | E29: =E$28*SUMPRODUCT($B$10*(1-$A29)^$B$25:$G$25+$E$4*(1-(1-$A29)^$B$25:$G$25)/$A29) -> 860443.66 | F29: =F$28*SUMPRODUCT($B$10*(1-$A29)^$B$25:$G$25+$E$4*(1-(1-$A29)^$B$25:$G$25)/$A29) -> 903465.84
A30: 0.015 | B30: =B$28*SUMPRODUCT($B$10*(1-$A30)^$B$25:$G$25+$E$4*(1-(1-$A30)^$B$25:$G$25)/$A30) -> 719944.38 | C30: =C$28*SUMPRODUCT($B$10*(1-$A30)^$B$25:$G$25+$E$4*(1-(1-$A30)^$B$25:$G$25)/$A30) -> 762294.05 | D30: =D$28*SUMPRODUCT($B$10*(1-$A30)^$B$25:$G$25+$E$4*(1-(1-$A30)^$B$25:$G$25)/$A30) -> 804643.72 | E30: =E$28*SUMPRODUCT($B$10*(1-$A30)^$B$25:$G$25+$E$4*(1-(1-$A30)^$B$25:$G$25)/$A30) -> 846993.39 | F30: =F$28*SUMPRODUCT($B$10*(1-$A30)^$B$25:$G$25+$E$4*(1-(1-$A30)^$B$25:$G$25)/$A30) -> 889343.06
A31: 0.02 | B31: =B$28*SUMPRODUCT($B$10*(1-$A31)^$B$25:$G$25+$E$4*(1-(1-$A31)^$B$25:$G$25)/$A31) -> 708693.85 | C31: =C$28*SUMPRODUCT($B$10*(1-$A31)^$B$25:$G$25+$E$4*(1-(1-$A31)^$B$25:$G$25)/$A31) -> 750381.72 | D31: =D$28*SUMPRODUCT($B$10*(1-$A31)^$B$25:$G$25+$E$4*(1-(1-$A31)^$B$25:$G$25)/$A31) -> 792069.59 | E31: =E$28*SUMPRODUCT($B$10*(1-$A31)^$B$25:$G$25+$E$4*(1-(1-$A31)^$B$25:$G$25)/$A31) -> 833757.47 | F31: =F$28*SUMPRODUCT($B$10*(1-$A31)^$B$25:$G$25+$E$4*(1-(1-$A31)^$B$25:$G$25)/$A31) -> 875445.34
A32: 0.025 | B32: =B$28*SUMPRODUCT($B$10*(1-$A32)^$B$25:$G$25+$E$4*(1-(1-$A32)^$B$25:$G$25)/$A32) -> 697622.84 | C32: =C$28*SUMPRODUCT($B$10*(1-$A32)^$B$25:$G$25+$E$4*(1-(1-$A32)^$B$25:$G$25)/$A32) -> 738659.47 | D32: =D$28*SUMPRODUCT($B$10*(1-$A32)^$B$25:$G$25+$E$4*(1-(1-$A32)^$B$25:$G$25)/$A32) -> 779696.11 | E32: =E$28*SUMPRODUCT($B$10*(1-$A32)^$B$25:$G$25+$E$4*(1-(1-$A32)^$B$25:$G$25)/$A32) -> 820732.75 | F32: =F$28*SUMPRODUCT($B$10*(1-$A32)^$B$25:$G$25+$E$4*(1-(1-$A32)^$B$25:$G$25)/$A32) -> 861769.39
A33: 0.03 | B33: =B$28*SUMPRODUCT($B$10*(1-$A33)^$B$25:$G$25+$E$4*(1-(1-$A33)^$B$25:$G$25)/$A33) -> 686728.71 | C33: =C$28*SUMPRODUCT($B$10*(1-$A33)^$B$25:$G$25+$E$4*(1-(1-$A33)^$B$25:$G$25)/$A33) -> 727124.52 | D33: =D$28*SUMPRODUCT($B$10*(1-$A33)^$B$25:$G$25+$E$4*(1-(1-$A33)^$B$25:$G$25)/$A33) -> 767520.32 | E33: =E$28*SUMPRODUCT($B$10*(1-$A33)^$B$25:$G$25+$E$4*(1-(1-$A33)^$B$25:$G$25)/$A33) -> 807916.13 | F33: =F$28*SUMPRODUCT($B$10*(1-$A33)^$B$25:$G$25+$E$4*(1-(1-$A33)^$B$25:$G$25)/$A33) -> 848311.94

Sheet Checks
A2: Check | B2: Pass? | C2: Value
A3: BvA: mapped actuals tie to GL | B3: =BvA!D14=0 -> TRUE | C3: =BvA!D14 -> 0
A4: PivotLab: cross-tab ties to BvA | B4: =PivotLab!B10=0 -> TRUE | C4: =PivotLab!B10 -> 0
A5: PVM: price+volume+mix = total | B5: =ROUND(PVM!N8,6)=0 -> TRUE | C5: =PVM!N8 -> 0
A6: CostVar: rate+volume = total | B6: =CostVar!B13=0 -> TRUE | C6: =CostVar!B13 -> 0
A7: BankRec: adjusted balances agree | B7: =BankRec!B19=0 -> TRUE | C7: =BankRec!B19 -> 0
A8: Forecast: seasonal index averages 1 | B8: =ROUND(Forecast!M17,9)=1 -> TRUE | C8: =Forecast!M17 -> 1
A9: Drivers: schedule = closed form | B9: =ROUND(Drivers!H18-INDEX(Drivers!B21:D21,Drivers!C8),2)=0 -> TRUE | C9: =Drivers!H18-INDEX(Drivers!B21:D21,Drivers!C8) -> 0
A10: ALL CONTROL CHECKS PASS | B10: =COUNTIF(B3:B9,FALSE())=0 -> TRUE
A12: Open item (informational): AR subledger vs GL difference | C12: =ARSummary!B19 -> 100
